<?xml version="1.0" encoding="UTF-8"?>
<!-- Generated by org.testng.reporters.JUnitXMLReporter -->
<testsuite ignored="0" hostname="DESKTOP-MNK2190" failures="1" tests="4" name="retry test-1" time="0.124" errors="0" timestamp="2021-08-05T11:45:27 IST">
  <testcase classname="retry_failed_case.Test_login" name="addProduct" time="0.036">
    <skipped/>
  </testcase> <!-- addProduct -->
  <testcase classname="retry_failed_case.Test_login" name="addProduct" time="0.003">
    <skipped/>
  </testcase> <!-- addProduct -->
  <testcase classname="retry_failed_case.Test_login" name="addProduct" time="0.004">
    <failure type="java.lang.AssertionError" message="Executing failed test">
      <![CDATA[java.lang.AssertionError: Executing failed test
at retry_failed_case.Test_login.addProduct(Test_login.java:18)
at java.base/java.util.ArrayList.forEach(ArrayList.java:1511)
... Removed 28 stack frames]]>
    </failure>
  </testcase> <!-- addProduct -->
  <testcase classname="retry_failed_case.Test_login" name="doLogin" time="0.002"/>
</testsuite> <!-- retry test-1 -->
